Workbook
Name C2ؤ1451: #REF!

Sheet 00_Raw
A1: order_id | B1: order_date | C1: order_time | D1: channel | E1: item_name | F1: category | G1: quantity | H1: unit_price | I1: total_price | J1: payment_method | K1: discount_pct | L1: customer_rating | M1: server_name
A2: ORD-00001 | B2: 2026-02-01 | C2: 14:55 | D2: Dine-in | E2: Tea | F2: Beverages | G2: 2 | H2: 1000 | I2: 2000 | J2: Cash | M2: Noor Kadhim
A3: ORD-00002 | B3: 2026-02-01 | C3: 20:24 | D3: Dine-in | E3: Chicken Tikka | F3: Grills | G3: 3 | H3: 15000 | I3: 45000 | J3: Card | M3: Ali Hassan
A4: ORD-00003 | B4: 2026-02-01 | C4: 20:26 | D4: Dine-in | E4: Falafel Sandwich | F4: Sandwiches | G4: 1 | H4: 3000 | I4: 3000 | J4: Cash | M4: Mustafa Karim
A5: ORD-00003 | B5: 2026-02-01 | C5: 20:26 | D5: Dine-in | E5: Falafel Sandwich | F5: Sandwiches | G5: 1 | H5: 3000 | I5: 3000 | J5: Cash | M5: Mustafa Karim
A6: ORD-00004 | B6: 2026-02-01 | C6: 20:50 | D6: Delivery | E6: Hummus | F6: Appetizers | G6: 1 | H6: 4000 | I6: 4000 | J6: Cash | M6: Zainab Salim
A7: ORD-00005 | B7: 2026-02-01 | C7: 22:04 | D7: Delivery | E7: Mixed Grill Platter | F7: Grills | G7: 1 | H7: 25000 | I7: 25000 | J7: Card | K7: 10 | L7: 5 | M7: Mustafa Karim
A8: ORD-00006 | B8: 2026-02-01 | C8: 22:53 | D8: Delivery | E8: Lamb Kebab | F8: Grills | G8: 1 | H8: 18000 | I8: 18000 | J8: Cash | M8: Ali Hassan
A9: ORD-00007 | B9: 2026-02-02 | C9: 20:15 | D9: Dine-in | E9: Soft Drink | F9: Beverages | G9: 1 | H9: 1500 | I9: 1500 | J9: Cash | L9: 4 | M9: Ali Hassan
A10: ORD-00008 | B10: 2026-02-02 | C10: 20:25 | D10: Dine-in | E10: Tea | F10: Beverages | G10: 1 | H10: 1000 | I10: 1000 | J10: Cash | L10: 3 | M10: Ali Hassan
A11: ORD-00009 | B11: 2026-02-02 | C11: 20:45 | D11: Takeaway | E11: Chicken Tikka | F11: Grills | G11: 1 | H11: 15000 | I11: 15000 | J11: Card | M11: Ali Hassan
A12: ORD-00010 | B12: 2026-02-02 | C12: 20:50 | D12: Dine-in | E12: Soft Drink | H12: 1500 | I12: 1500 | J12: Cash | M12: Omar Jabbar
A13: ORD-00011 | B13: 2026-02-02 | C13: 21:26 | D13: Dine-in | E13: Shwarma Sandwich | F13: Sandwiches | G13: 1 | H13: 5000 | I13: 5000 | J13: Cash | M13: Zainab Salim
A14: ORD-00012 | B14: 02/02/2026 | C14: 23:49 | D14: Delivery | E14: Chicken Sandwich | F14: Sandwiches | G14: 1 | H14: 6000 | I14: 6000 | J14: Cash | L14: 4 | M14: Mustafa Karim
A15: ORD-00013 | B15: 2026-02-03 | C15: 19:22 | D15: dine in | E15: Tea | F15: Beverages | G15: 1 | I15: 1000 | J15: Cash | L15: 4 | M15: Noor Kadhim
A16: ORD-00014 | B16: 2026-02-03 | C16: 20:11 | D16: Dine-in | E16: CHICKEN TIKKA | F16: Grills | G16: 1 | I16: 13500 | J16: Cash | K16: 10 | M16: Omar Jabbar
A17: ORD-00015 | B17: 2026-02-03 | C17: 20:16 | D17: Delivery | E17: Falafel Sandwich | F17: Sandwiches | H17: 3000 | I17: 3000 | J17: Card | L17: 3 | M17: Zainab Salim
A18: ORD-00016 | B18: 2026-02-03 | C18: 22:17 | D18: Delivery | E18: Fattoush Salad | F18: Appetizers | G18: 2 | H18: 5000 | I18: 10000 | J18: Cash | L18: 4 | M18: Ali Hassan
A19: ORD-00017 | B19: 2026-02-03 | C19: 22:24 | D19: Delivery | E19: Tea | G19: 1 | H19: 1000 | I19: 1000 | J19: Cash | M19: noor kadhim
A20: ORD-00018 | B20: 2026-02-04 | C20: 17:58 | D20: Dine-in | E20: Shawarma Sandwich | G20: 1 | H20: 5000 IQD | I20: 5000 | J20: Cash | M20: Ali Hassan
A21: ORD-00019 | B21: 2026-02-04 | C21: 19:59 | D21: Takeaway | E21: Kunafah | F21: Desserts | G21: 1 | H21: 7000 | I21: 7000 IQD | J21: Card | M21: Mustafa Karim
A22: ORD-00020 | B22: 2026-02-04 | C22: 20:23 | D22: Dine-in | E22: Hummus | F22: Appetizers | G22: 2 | H22: 4000 | I22: 8000 | J22: Cash | M22: Omar Jabbar
A23: ORD-00021 | B23: 2026-02-04 | C23: 20:56 | D23: Dine-in | E23: Mixed Grill Platter | F23: Grills | G23: 1 | H23: 25000 | I23: 25000 | J23: Cash | M23: Ali Hassan
A24: ORD-00022 | B24: 2026-02-04 | C24: 22:48 | D24: Delivery | E24: Fattoush Salad | F24: Appetizers | G24: 1 | H24: 5000 | I24: 4000 | J24: Cash | K24: 20 | M24: Zainab Salim
A25: ORD-00023 | B25: 2026-02-05 | C25: 13:57 | D25: Dine-in | E25: Tea | F25: Beverages | G25: 1 | H25: 1000 | I25: 1000 | J25: Cash | M25: Noor Kadhim
A26: ORD-00024 | B26: 2026-02-05 | C26: 17:33 | D26: takeaway | E26: Chicken Tikka | F26: Grills | G26: 2 | H26: 15000 | I26: 30000 IQD | J26: CASH | L26: 5 | M26: Mustafa Karim
A27: ORD-00025 | B27: 2026-02-05 | C27: 17:42 | D27: Dine-in | E27: Falafel Sandwich | F27: Sandwiches | G27: 1 | H27: 3,000 | I27: 3000 | J27: Cash | M27: Mustafa Karim
A28: ORD-00026 | B28: 2026-02-05 | C28: 18:31 | D28: dine-in | E28: Soft Drink | F28: Beverages | G28: 1 | H28: 1500 | I28: 1500 | J28: Cash | M28: Omar Jabbar
A29: ORD-00027 | B29: 2026-02-05 | C29: 18:44 | D29: Takeaway | E29: Chicken Sandwich | G29: 1 | H29: 6000 | I29: 6000 | J29: Cash | M29: Ali Hassan
A30: ORD-00028 | B30: 2026-02-05 | C30: 19:01 | D30: Dine-in | E30: Lamb Kebab | F30: Grills | G30: 2 | H30: 18000 | I30: 36000 | J30: Cash | M30: Zainab Salim
A31: ORD-00029 | B31: 2026-02-05 | C31: 19:17 | D31: Delivery | E31: Lamb Kebab | F31: Grills | G31: 1 | H31: 18000 | I31: 18000 | J31: Cash | K31: 15 | M31: Zainab Salim
A32: ORD-00030 | B32: 2026-02-05 | C32: 20:00 | D32: Delivery | E32: Shish Tawook | F32: Grills | G32: 3 | H32: 16000 | I32: 48000 | J32: Card | M32: Ali Hassan
A33: ORD-00031 | B33: 2026-02-05 | C33: 21:19 | D33: Dine-in | E33: Chicken Sandwich | F33: Sandwiches | G33: 1 | H33: 6000 | I33: 6000 | J33: Cash | M33: Omar Jabbar
A34: ORD-00032 | B34: 2026-02-05 | C34: 21:25 | D34: Dine-in | E34: Shawarma Sandwich | F34: Sandwiches | G34: 1 | H34: 5000 | I34: 5000 | J34: Cash | M34: Noor Kadhim
A35: ORD-00033 | B35: 2026-02-05 | C35: 21:55 | D35: Dine-in | E35: Tea | G35: 2 | H35: 1000 | I35: 2000 | J35: Cash | M35: omar jabbar
A36: ORD-00034 | B36: 2026-02-05 | C36: 22:04 | D36: Delivery | E36: Lamb Kebab | F36: Grills | G36: 1 | H36: 18000 | I36: 18000 | J36: Cash | M36: Ali Hassan
A37: ORD-00035 | B37: 2026-02-05 | C37: 22:30 | D37: Dine-in | E37: Softdrink | F37: Beverages | G37: 1 | I37: 1350 | J37: Cash | K37: 10 | M37: Omar Jabbar
A38: ORD-00036 | B38: 2026-02-05 | C38: 22:37 | D38: Dine-in | E38: Baklava | F38: Desserts | G38: 1 | H38: 6000 | I38: 6000 | J38: Cash | M38: Noor Kadhim
A39: ORD-00037 | B39: 2026-02-05 | C39: 23:14 | D39: Dine-in | E39: Tea | F39: Beverages | G39: 1 | H39: 1000 | I39: 1000 | J39: Cash | L39: 5 | M39: Zainab Salim
A40: ORD-00038 | B40: 2026-02-06 | C40: 11:27 | D40: Dine-in | E40: Lamb Kebab | F40: Grills | G40: 1 | H40: 18000 | I40: 18000 | J40: Cash | M40: omar jabbar
...

Sheet 01-clean
A1: order_id | B1: order_date | C1: order_time | D1: Hour | E1: weekday | F1: channel | G1: item_name | H1: category | I1: quantity | J1: unit_price | K1: total_price | L1: payment_method | M1: discount_pct | N1: customer_rating | O1: server_name
A2: ORD-00001 | B2: 46054 | C2: 0.62152778 | D2: =HOUR(C2) -> 14 | E2: =TEXT(B2,"dddd") -> Sunday | F2: Dine-in | G2: Tea | H2: Beverages | I2: 2 | J2: 1000 | K2: 2000 | L2: Cash | M2: 0 | O2: Noor Kadhim
A3: ORD-00002 | B3: 46054 | C3: 0.85 | D3: =HOUR(C3) -> 20 | E3: =TEXT(B3,"dddd") -> Sunday | F3: Dine-in | G3: Chicken Tikka | H3: Grills | I3: 3 | J3: 15000 | K3: 45000 | L3: Card | M3: 0 | O3: Ali Hassan
A4: ORD-00003 | B4: 46054 | C4: 0.85138889 | D4: =HOUR(C4) -> 20 | E4: =TEXT(B4,"dddd") -> Sunday | F4: Dine-in | G4: Falafel Sandwich | H4: Sandwiches | I4: 1 | J4: 3000 | K4: 3000 | L4: Cash | M4: 0 | O4: Mustafa Karim
A5: ORD-00004 | B5: 46054 | C5: 0.86805556 | D5: =HOUR(C5) -> 20 | E5: =TEXT(B5,"dddd") -> Sunday | F5: Delivery | G5: Hummus | H5: Appetizers | I5: 1 | J5: 4000 | K5: 4000 | L5: Cash | M5: 0 | O5: Zainab Salim
A6: ORD-00005 | B6: 46054 | C6: 0.91944444 | D6: =HOUR(C6) -> 22 | E6: =TEXT(B6,"dddd") -> Sunday | F6: Delivery | G6: Mixed Grill Platter | H6: Grills | I6: 1 | J6: 25000 | K6: 22500 | L6: Card | M6: 0.1 | N6: 5 | O6: Mustafa Karim
A7: ORD-00006 | B7: 46054 | C7: 0.95347222 | D7: =HOUR(C7) -> 22 | E7: =TEXT(B7,"dddd") -> Sunday | F7: Delivery | G7: Lamb Kebab | H7: Grills | I7: 1 | J7: 18000 | K7: 18000 | L7: Cash | M7: 0 | O7: Ali Hassan
A8: ORD-00007 | B8: 46055 | C8: 0.84375 | D8: =HOUR(C8) -> 20 | E8: =TEXT(B8,"dddd") -> Monday | F8: Dine-in | G8: Soft Drink | H8: Beverages | I8: 1 | J8: 1500 | K8: 1500 | L8: Cash | M8: 0 | N8: 4 | O8: Ali Hassan
A9: ORD-00008 | B9: 46055 | C9: 0.85069444 | D9: =HOUR(C9) -> 20 | E9: =TEXT(B9,"dddd") -> Monday | F9: Dine-in | G9: Tea | H9: Beverages | I9: 1 | J9: 1000 | K9: 1000 | L9: Cash | M9: 0 | N9: 3 | O9: Ali Hassan
A10: ORD-00009 | B10: 46055 | C10: 0.86458333 | D10: =HOUR(C10) -> 20 | E10: =TEXT(B10,"dddd") -> Monday | F10: Takeaway | G10: Chicken Tikka | H10: Grills | I10: 1 | J10: 15000 | K10: 15000 | L10: Card | M10: 0 | O10: Ali Hassan
A11: ORD-00010 | B11: 46055 | C11: 0.86805556 | D11: =HOUR(C11) -> 20 | E11: =TEXT(B11,"dddd") -> Monday | F11: Dine-in | G11: Soft Drink | H11: =VLOOKUP(G11,'02_Menu_Lookup'!$A$2:$C$16,2,FALSE) -> Beverages | I11: =K11/J11 -> 1 | J11: 1500 | K11: 1500 | L11: Cash | M11: 0 | O11: Omar Jabbar
A12: ORD-00011 | B12: 46055 | C12: 0.89305556 | D12: =HOUR(C12) -> 21 | E12: =TEXT(B12,"dddd") -> Monday | F12: Dine-in | G12: Shawarma Sandwich | H12: Sandwiches | I12: 1 | J12: 5000 | K12: 5000 | L12: Cash | M12: 0 | O12: Zainab Salim
A13: ORD-00012 | B13: 46055 | C13: 0.99236111 | D13: =HOUR(C13) -> 23 | E13: =TEXT(B13,"dddd") -> Monday | F13: Delivery | G13: Chicken Sandwich | H13: Sandwiches | I13: 1 | J13: 6000 | K13: 6000 | L13: Cash | M13: 0 | N13: 4 | O13: Mustafa Karim
A14: ORD-00013 | B14: 46056 | C14: 0.80694444 | D14: =HOUR(C14) -> 19 | E14: =TEXT(B14,"dddd") -> Tuesday | F14: Dine-in | G14: Tea | H14: Beverages | I14: 1 | J14: =K14/I14 -> 1000 | K14: 1000 | L14: Cash | M14: 0 | N14: 4 | O14: Noor Kadhim
A15: ORD-00014 | B15: 46056 | C15: 0.84097222 | D15: =HOUR(C15) -> 20 | E15: =TEXT(B15,"dddd") -> Tuesday | F15: Dine-in | G15: Chicken Tikka | H15: Grills | I15: 1 | J15: 13500 | K15: 12150 | L15: Cash | M15: 0.1 | O15: Omar Jabbar
A16: ORD-00015 | B16: 46056 | C16: 0.84444444 | D16: =HOUR(C16) -> 20 | E16: =TEXT(B16,"dddd") -> Tuesday | F16: Delivery | G16: Falafel Sandwich | H16: Sandwiches | I16: =K16/J16 -> 1 | J16: 3000 | K16: 3000 | L16: Card | M16: 0 | N16: 3 | O16: Zainab Salim
A17: ORD-00016 | B17: 46056 | C17: 0.92847222 | D17: =HOUR(C17) -> 22 | E17: =TEXT(B17,"dddd") -> Tuesday | F17: Delivery | G17: Fattoush Salad | H17: Appetizers | I17: 2 | J17: 5000 | K17: 10000 | L17: Cash | M17: 0 | N17: 4 | O17: Ali Hassan
A18: ORD-00017 | B18: 46056 | C18: 0.93333333 | D18: =HOUR(C18) -> 22 | E18: =TEXT(B18,"dddd") -> Tuesday | F18: Delivery | G18: Tea | H18: =VLOOKUP(G18,'02_Menu_Lookup'!$A$2:$C$16,2,FALSE) -> Beverages | I18: 1 | J18: 1000 | K18: 1000 | L18: Cash | M18: 0 | O18: Noor Kadhim
A19: ORD-00018 | B19: 46057 | C19: 0.74861111 | D19: =HOUR(C19) -> 17 | E19: =TEXT(B19,"dddd") -> Wednesday | F19: Dine-in | G19: Shawarma Sandwich | H19: =VLOOKUP(G19,'02_Menu_Lookup'!$A$2:$C$16,2,FALSE) -> Sandwiches | I19: 1 | J19: 5000 | K19: 5000 | L19: Cash | M19: 0 | O19: Ali Hassan
A20: ORD-00019 | B20: 46057 | C20: 0.83263889 | D20: =HOUR(C20) -> 19 | E20: =TEXT(B20,"dddd") -> Wednesday | F20: Takeaway | G20: Kunafa | H20: Desserts | I20: 1 | J20: 7000 | K20: 7000 | L20: Card | M20: 0 | O20: Mustafa Karim
A21: ORD-00020 | B21: 46057 | C21: 0.84930556 | D21: =HOUR(C21) -> 20 | E21: =TEXT(B21,"dddd") -> Wednesday | F21: Dine-in | G21: Hummus | H21: Appetizers | I21: 2 | J21: 4000 | K21: 8000 | L21: Cash | M21: 0 | O21: Omar Jabbar
A22: ORD-00021 | B22: 46057 | C22: 0.87222222 | D22: =HOUR(C22) -> 20 | E22: =TEXT(B22,"dddd") -> Wednesday | F22: Dine-in | G22: Mixed Grill Platter | H22: Grills | I22: 1 | J22: 25000 | K22: 25000 | L22: Cash | M22: 0 | O22: Ali Hassan
A23: ORD-00022 | B23: 46057 | C23: 0.95 | D23: =HOUR(C23) -> 22 | E23: =TEXT(B23,"dddd") -> Wednesday | F23: Delivery | G23: Fattoush Salad | H23: Appetizers | I23: 1 | J23: 5000 | K23: 4000 | L23: Cash | M23: 0.2 | O23: Zainab Salim
A24: ORD-00023 | B24: 46058 | C24: 0.58125 | D24: =HOUR(C24) -> 13 | E24: =TEXT(B24,"dddd") -> Thursday | F24: Dine-in | G24: Tea | H24: Beverages | I24: 1 | J24: 1000 | K24: 1000 | L24: Cash | M24: 0 | O24: Noor Kadhim
A25: ORD-00024 | B25: 46058 | C25: 0.73125 | D25: =HOUR(C25) -> 17 | E25: =TEXT(B25,"dddd") -> Thursday | F25: Takeaway | G25: Chicken Tikka | H25: Grills | I25: 2 | J25: 15000 | K25: 30000 | L25: Cash | M25: 0 | N25: 5 | O25: Mustafa Karim
A26: ORD-00025 | B26: 46058 | C26: 0.7375 | D26: =HOUR(C26) -> 17 | E26: =TEXT(B26,"dddd") -> Thursday | F26: Dine-in | G26: Falafel Sandwich | H26: Sandwiches | I26: 1 | J26: 3000 | K26: 3000 | L26: Cash | M26: 0 | O26: Mustafa Karim
A27: ORD-00026 | B27: 46058 | C27: 0.77152778 | D27: =HOUR(C27) -> 18 | E27: =TEXT(B27,"dddd") -> Thursday | F27: Dine-in | G27: Soft Drink | H27: Beverages | I27: 1 | J27: 1500 | K27: 1500 | L27: Cash | M27: 0 | O27: Omar Jabbar
A28: ORD-00027 | B28: 46058 | C28: 0.78055556 | D28: =HOUR(C28) -> 18 | E28: =TEXT(B28,"dddd") -> Thursday | F28: Takeaway | G28: Chicken Sandwich | H28: =VLOOKUP(G28,'02_Menu_Lookup'!$A$2:$C$16,2,FALSE) -> Sandwiches | I28: 1 | J28: 6000 | K28: 6000 | L28: Cash | M28: 0 | O28: Ali Hassan
A29: ORD-00028 | B29: 46058 | C29: 0.79236111 | D29: =HOUR(C29) -> 19 | E29: =TEXT(B29,"dddd") -> Thursday | F29: Dine-in | G29: Lamb Kebab | H29: Grills | I29: 2 | J29: 18000 | K29: 36000 | L29: Cash | M29: 0 | O29: Zainab Salim
A30: ORD-00029 | B30: 46058 | C30: 0.80347222 | D30: =HOUR(C30) -> 19 | E30: =TEXT(B30,"dddd") -> Thursday | F30: Delivery | G30: Lamb Kebab | H30: Grills | I30: 1 | J30: 18000 | K30: 15300 | L30: Cash | M30: 0.15 | O30: Zainab Salim
A31: ORD-00030 | B31: 46058 | C31: 0.83333333 | D31: =HOUR(C31) -> 20 | E31: =TEXT(B31,"dddd") -> Thursday | F31: Delivery | G31: Shish Tawook | H31: Grills | I31: 3 | J31: 16000 | K31: 48000 | L31: Card | M31: 0 | O31: Ali Hassan
A32: ORD-00031 | B32: 46058 | C32: 0.88819444 | D32: =HOUR(C32) -> 21 | E32: =TEXT(B32,"dddd") -> Thursday | F32: Dine-in | G32: Chicken Sandwich | H32: Sandwiches | I32: 1 | J32: 6000 | K32: 6000 | L32: Cash | M32: 0 | O32: Omar Jabbar
A33: ORD-00032 | B33: 46058 | C33: 0.89236111 | D33: =HOUR(C33) -> 21 | E33: =TEXT(B33,"dddd") -> Thursday | F33: Dine-in | G33: Shawarma Sandwich | H33: Sandwiches | I33: 1 | J33: 5000 | K33: 5000 | L33: Cash | M33: 0 | O33: Noor Kadhim
A34: ORD-00033 | B34: 46058 | C34: 0.91319444 | D34: =HOUR(C34) -> 21 | E34: =TEXT(B34,"dddd") -> Thursday | F34: Dine-in | G34: Tea | H34: =VLOOKUP(G34,'02_Menu_Lookup'!$A$2:$C$16,2,FALSE) -> Beverages | I34: 2 | J34: 1000 | K34: 2000 | L34: Cash | M34: 0 | O34: Omar Jabbar
A35: ORD-00034 | B35: 46058 | C35: 0.91944444 | D35: =HOUR(C35) -> 22 | E35: =TEXT(B35,"dddd") -> Thursday | F35: Delivery | G35: Lamb Kebab | H35: Grills | I35: 1 | J35: 18000 | K35: 18000 | L35: Cash | M35: 0 | O35: Ali Hassan
A36: ORD-00035 | B36: 46058 | C36: 0.9375 | D36: =HOUR(C36) -> 22 | E36: =TEXT(B36,"dddd") -> Thursday | F36: Dine-in | G36: Soft Drink | H36: Beverages | I36: 1 | J36: 1350 | K36: 1215 | L36: Cash | M36: 0.1 | O36: Omar Jabbar
A37: ORD-00036 | B37: 46058 | C37: 0.94236111 | D37: =HOUR(C37) -> 22 | E37: =TEXT(B37,"dddd") -> Thursday | F37: Dine-in | G37: Baklava | H37: Desserts | I37: 1 | J37: 6000 | K37: 6000 | L37: Cash | M37: 0 | O37: Noor Kadhim
A38: ORD-00037 | B38: 46058 | C38: 0.96805556 | D38: =HOUR(C38) -> 23 | E38: =TEXT(B38,"dddd") -> Thursday | F38: Dine-in | G38: Tea | H38: Beverages | I38: 1 | J38: 1000 | K38: 1000 | L38: Cash | M38: 0 | N38: 5 | O38: Zainab Salim
A39: ORD-00038 | B39: 46059 | C39: 0.47708333 | D39: =HOUR(C39) -> 11 | E39: =TEXT(B39,"dddd") -> Friday | F39: Dine-in | G39: Lamb Kebab | H39: Grills | I39: 1 | J39: 18000 | K39: 18000 | L39: Cash | M39: 0 | O39: Omar Jabbar
A40: ORD-00039 | B40: 46175 | C40: 0.50833333 | D40: =HOUR(C40) -> 12 | E40: =TEXT(B40,"dddd") -> Tuesday | F40: Dine-in | G40: Tea | H40: Beverages | I40: 1 | J40: 1000 | K40: 1000 | L40: Card | M40: 0 | N40: 4 | O40: Noor Kadhim
...

Sheet 02_Menu_Lookup
A1: item_name | B1: category | C1: unit_price
A2: Mixed Grill Platter | B2: Grills | C2: 25000
A3: Lamb Kebab | B3: Grills | C3: 18000
A4: Shish Tawook | B4: Grills | C4: 16000
A5: Chicken Tikka | B5: Grills | C5: 15000
A6: Chicken Sandwich | B6: Sandwiches | C6: 6000
A7: Shawarma Sandwich | B7: Sandwiches | C7: 5000
A8: Falafel Sandwich | B8: Sandwiches | C8: 3000
A9: Fattoush Salad | B9: Appetizers | C9: 5000
A10: Mutabbal | B10: Appetizers | C10: 4500
A11: Hummus | B11: Appetizers | C11: 4000
A12: Kunafa | B12: Desserts | C12: 7000
... A16: Tea | B16: Beverages | C16: 1000

Sheet 03-ِAnalysis
A1: order_date | B1: (ALL)
A2: Monthly Revenue by Channel | G2: Peak Hours Matrix by Day of Week
B3: ز | G3: .2 | H3: . | Q3: Sales Breakdown by Category
B4: Delivery | C4: Dine-in | D4: Takeaway | E4: Grand Total | G4: Hour | H4: Sunday | I4: Monday | J4: Tuesday | K4: Wednesday | L4: Thursday | M4: Friday | N4: Saturday | O4: Grand Total | Q4: category | R4: SUM o total_price
B5: 4162330 | C5: 6971020 | D5: 2849025 | E5: 13982375 | G5: 11 | H5: 3 | I5: 3 | J5: 1 | K5: 3 | L5: 1 | M5: 3 | N5: 2 | O5: 16 | Q5: Appetizers | R5: 0.0689021
G6: 12 | H6: 4 | I6: 4 | J6: 5 | K6: 9 | L6: 15 | M6: 11 | N6: 11 | O6: 59 | Q6: Beverages | R6: 0.054502186
G7: 13 | H7: 5 | I7: 12 | J7: 13 | K7: 18 | L7: 15 | M7: 17 | N7: 17 | O7: 97 | Q7: Desserts | R7: 0.057357924
G8: 14 | H8: 10 | I8: 7 | J8: 7 | K8: 11 | L8: 16 | M8: 23 | N8: 19 | O8: 93 | Q8: Grills | R8: 0.64173004
G9: 15 | H9: 4 | I9: 6 | J9: 7 | K9: 6 | L9: 11 | M9: 14 | N9: 5 | O9: 53 | Q9: Sandwiches | R9: 0.17750776
G10: 16 | H10: 3 | I10: 3 | J10: 3 | K10: 6 | L10: 3 | M10: 8 | N10: 8 | O10: 34 | Q10: Grand Total | R10: 1
G11: 17 | H11: 6 | I11: 4 | J11: 4 | K11: 6 | L11: 9 | M11: 7 | N11: 5 | O11: 41
G12: 18 | H12: 7 | I12: 5 | J12: 8 | K12: 8 | L12: 15 | M12: 15 | N12: 9 | O12: 67
G13: 19 | H13: 17 | I13: 22 | J13: 18 | K13: 20 | L13: 25 | M13: 42 | N13: 35 | O13: 179
G14: 20 | H14: 29 | I14: 35 | J14: 28 | K14: 37 | L14: 30 | M14: 54 | N14: 54 | O14: 267
G15: 21 | H15: 23 | I15: 31 | J15: 19 | K15: 37 | L15: 44 | M15: 64 | N15: 48 | O15: 266
G16: 22 | H16: 24 | I16: 24 | J16: 22 | K16: 20 | L16: 33 | M16: 38 | N16: 36 | O16: 197
G17: 23 | H17: 10 | I17: 5 | J17: 6 | K17: 14 | L17: 24 | M17: 10 | N17: 12 | O17: 81
G18: Grand Total | H18: 145 | I18: 161 | J18: 141 | K18: 195 | L18: 241 | M18: 306 | N18: 261 | O18: 1450
A22: Average Customer Rating per Item | D22: Total Orders by Hour of Day | G22: Monthly Revenue Share by Payment Method | L22: Top 10 Best Selling Items
A23: item_name | B23: AVERAGE rating | D23: hour | E23: COUNTA of order_id | G23: . | H23: .
A24: Baklava | B24: 3.8 | D24: 11 | E24: 16 | G24: order_date - Month | H24: Cash | I24: Card | J24: Grand Total | L24: item_name | M24: SUM of quantity | N24: SUM of total_price
A25: Chicken Sandwich | B25: 4.04 | D25: 12 | E25: 59 | G25: Jan | H25: 0.0014303722 | I25: 0.00035759304 | J25: 0.0017879652 | L25: Baklava | M25: 45 | N25: 263700
A26: Chicken Tikka | B26: 4.0571429 | D26: 13 | E26: 97 | G26: Feb | H26: 0.12328199 | I26: 0.038437676 | J26: 0.16171966 | L26: Chicken Sandwich | M26: 164 | N26: 968100
A27: Falafel Sandwich | B27: 3.75 | D27: 14 | E27: 93 | G27: Mar | H27: 0.12233794 | I27: 0.034935052 | J27: 0.157273 | L27: Chicken Tikka | M27: 122 | N27: 1807650
A28: Fattoush Salad | B28: 3.8947368 | D28: 15 | E28: 53 | G28: Apr | H28: 0.11943643 | I28: 0.036726593 | J28: 0.15616303 | L28: Falafel Sandwich | M28: 147 | N28: 426780
A29: Fresh Lemon Mint | B29: 4.5833333 | D29: 16 | E29: 34 | G29: May | H29: 0.12065904 | I29: 0.056225069 | J29: 0.17688411 | L29: Fattoush Salad | M29: 75 | N29: 369500
A30: Hummus | B30: 4.1219512 | D30: 17 | E30: 41 | G30: Jun | H30: 0.086085161 | I30: 0.071643766 | J30: 0.15772893 | L30: Fresh Lemon Mint | M30: 43 | N30: 128400
A31: Kunafa | B31: 4.2173913 | D31: 18 | E31: 67 | G31: Jul | H31: 0.092437801 | I31: 0.087445445 | J31: 0.17988325 | L31: Hummus | M31: 116 | N31: 456890
A32: Lamb Kebab | B32: 4.15625 | D32: 19 | E32: 179 | G32: Aug | H32: 0.0010012605 | I32: 0.00040765607 | J32: 0.0014089166 | L32: Kunafa | M32: 78 | N32: 538300
A33: Mixed Grill Platter | B33: 4.3428571 | D33: 20 | E33: 267 | G33: Sep | H33: 0.0018594838 | J33: 0.0018594838 | L33: Lamb Kebab | M33: 108 | N33: 1908900
A34: Mutabbal | B34: 2.5 | D34: 21 | E34: 266 | G34: Oct | H34: 0.00040872885 | I34: 0.0015018908 | J34: 0.0019106196 | L34: Mixed Grill Platter | M34: 134 | N34: 3260000
A35: Shawarma Sandwich | B35: 4.2131148 | D35: 22 | E35: 197 | G35: Nov | H35: 0.0022009852 | I35: 0.00071518608 | J35: 0.0029161713 | L35: Mutabbal | M35: 31 | N35: 137025
A36: Shish Tawook | B36: 4.2647059 | D36: 23 | E36: 81 | G36: Dec | H36: 0.00010727791 | I36: 0.00035759304 | J36: 0.00046487095 | L36: Shawarma Sandwich | M36: 222 | N36: 1087100
A37: Soft Drink | B37: 3.7972973 | D37: Grand Total | E37: 1450 | G37: Grand Total | H37: 0.67124648 | I37: 0.32875352 | J37: 1 | L37: Shish Tawook | M37: 128 | N37: 1996360
A38: Tea | B38: 3.9538462 | L38: Soft Drink | M38: 271 | N38: 397920
A39: Grand Total | B39: 4.0128205 | L39: Tea | M39: 239 | N39: 235750
L40: Grand Total | M40: 1923 | N40: 13982375

Sheet 04_Charts

Sheet 05_Cleaning_Log
A1: Log ID | B1: Issue Identified_Column(s) | C1: Original Problem Description | D1: Action Taken_Formula | E1: Tool Used_Row Count | F1: Impact
A2: Duplicate Records | B2: All Columns (A:Z) | C2: 50 identical duplicate order rows causing inflated sales metrics and distorted counts. | D2: Highlighted duplicate primary keys using Conditional Formatting, reviewed for exact matches, and removed all 50 duplicate records to streamline the dataset to 1,450 unique orders.. | E2: Tool Used: =COUNTIF(A:A, A1) > 1 + Data Cleanup tool / Remove Duplicates | F2: 50 rows removed (Reduced 1,500 to 1,450)
A3: Text Standardisation & Typo Correction | B3: item_name, category, payment_method, server_name | C3: Inconsistent text casing (e.g., lowercase entries), inconsistent payment method tags (e.g., CASH vs cash), typos in server names, and trailing whitespace across product and transaction details. | D3: Extracted unique string lists to locate all variant spellings and casing errors, trimmed hidden spaces, standardized text to Proper Case, and replaced incorrect entries with unified standard terms. | E3: =TRIM(), =PROPER(), =UNIQUE(), and Find & Replace | F3: 100+ rows cleaned and standardized across text columns
A4: Data Type & Formatting Corrections | B4: order_date, unit_price, total_price | C4: Dates were formatted as raw numbers/general text, and monetary values lacked standard currency formatting and thousand separators. | D4: Converted text numbers in the date column to proper Date data types (YYYY-MM-DD) and applied financial number formatting (comma separators) to price columns for clean visual presentation and accurate mathematical operations. | E4: Format $\rightarrow$ Number $\rightarrow$ Date and Format $\rightarrow$ Number $\rightarrow$ Financial / Custom Currency | F4: 1,450 clean rows
A5: Discount Logic & Price Reconciliation | B5: discount_pct, total_price, unit_price | C5: Discrepancies where discounts were flagged but not applied to totals. Additionally, text currency symbols (IQD) inside cells blocked direct mathematical formula evaluation. | D5: Temporarily removed the text currency symbol IQD from price cells to enable numeric math operations. Used a temporary helper column with a filter to recalculate true net totals for the 204 discounted orders, pasted the calculated values into total_price, and finally reapplied IQD standard currency formatting across the column. | E5: unit_price * quantity * (1 - (discount_pct / 100))via Helper Column + Filter + Paste Values + Custom Currency Formatting | F5: 204 discounted orders reconciled
A6: Missing Values & Data Imputation | B6: category, unit_price, total_price, quantity | C6: Missing values across key transactional fields (category: 87, unit_price: 68, total_price: 65, quantity: 25) following duplicate removal. Transformation / Action Taken: Imputed missing values to preserve record integrity. Cross-referenced item names against the master lookup tab (02_Menu_Lookup) to restore categories and base unit prices, while mathematically calculating missing total prices and quantities using dependent arithmetic formulas. | D6: Imputed missing values to preserve record integrity. Cross-referenced item names against the master lookup tab (02_Menu_Lookup) to restore categories and base unit prices, while mathematically calculating missing total prices and quantities using arithmetic formulas. | E6: IFERROR(VLOOKUP(A2, '02_Menu_Lookup'!A:C, 2, FALSE), unit_price * quantity) | F6: 245 missing data points imputed across 1,450 records
